Workbook

Sheet Case Study
A1: Ridge Business Center
A3: Ridge Business Center is a warehouse/office property in Charlotte. The property includes a well-maintained building totalling 50,000 sq ft in leasable area.
A4: The property has been offered for sale by the current owner at asking price of $5 Million. As a Financial Analyst of XYZ Investors, you are expected to identify if the property will
A5: be a good acquisition for the company. An investment must generate a minimum of 15% IRR for XYZ Investors.
A6: Please build a financial model using the assumptions below to provide an answer to the Management. Required sheets have been provided.
A8: Investment Assumptions
A9: Acquisition Date | B9: 44197
A10: Holding Period | B10: 5 years | C10: * time for which the property is owned
A11: Sale Date | B11: last day of 60th month
A12: Terminal Cap Rate | B12: 0.075 | C12: * This rate is used to determine Sale Price by the following formula: Sale Price= 5th Year NOI/Terminal Cap Rate
A13: Cost of Sale | B13: 0.02 | C13: * 2% of Sale Earnings go to broker/lawyer
A15: Loan Assumptions
A16: Loan Start Date | B16: 44197
A17: Term of Loan | B17: 5 years
A18: LTV | B18: 0.75 | C18: * of Price
A19: Interest Rate | B19: 0.04
A20: Loan Fees | B20: 0.01
A21: Amortization Period | B21: 25 years | C21: * Calculate monthly loan payments, you will need an amortization schedule
A23: Rent Assumptions
A24: 1) Assume rents increase every year on first day of the calendar year
A25: 2) Rents shown are Annual rents on a per square feet basis. Convert them to monthly rents and actual $ as and when required.
A26: 3) NNN leases are triple net leases, tenant has to pay their proportionate share of CAM, taxes and insurance over and above the rent
A27: 4) Consider Suite 1006 as vacant for the entire duration of 5 years
A29: Rent Roll ( As of 31 July, 2020)
A30: Suite | B30: Leased Area | C30: Status | D30: Lease Start Date | E30: Lease End Date | F30: Annual Rent PSF | G30: Rent Increase Date | H30: Rent Increase | I30: Lease Type
B31: (sq. ft) | D31: (mm/dd/yy) | E31: (mm/dd/yy) | F31: (as of 31 July, 20) | G31: (mm/dd/yy) | H31: Annual (%)
A32: 1001 | B32: 10000 | C32: Occupied | D32: 43160 | E32: =EOMONTH(D32,120) -> 46843 | F32: 12.15 | G32: 44197 | H32: 0.03 | I32: NNN
A33: 1002 | B33: 10000 | C33: Occupied | D33: 43617 | E33: =EOMONTH(D33,120) -> 47299 | F33: 11.5 | G33: 44197 | H33: 0.03 | I33: NNN
A34: 1003 | B34: 15000 | C34: Occupied | D34: 43831 | E34: =EOMONTH(D34,120) -> 47514 | F34: 10.75 | G34: 44197 | H34: 0.03 | I34: NNN
A35: 1004 | B35: 5000 | C35: Occupied | D35: 43160 | E35: =EOMONTH(D35,120) -> 46843 | F35: 12 | G35: 44197 | H35: 0.05 | I35: NNN
A36: 1005 | B36: 10000 | C36: Occupied | D36: 43617 | E36: =EOMONTH(D36,120) -> 47299 | F36: 12 | G36: 44197 | H36: 0.05 | I36: NNN
A37: 1006 | B37: 6000 | C37: Vacant
A38: Total | B38: =SUM(B32:B37) -> 56000 | F38: =SUMPRODUCT(F32:F36,B32:B36)/B38 -> 10.316964
A42: Expense Assumptions
A43: 1) All expenses are paid by landlord
A44: 2) All expenses grow 2% annually
A46: Expense Assumptions
A47: Expense Type | B47: Annual Expense ($)
A48: CAM | B48: 25000
A49: Taxes | B49: 75000 | D49: (Assumed CAM,Taxes and Insurance are paid proportionately by the tenants and remaining expenses are covered by the landlord)
...

Sheet Dashboard
A3: You must calculate the sections mentioned below on this page, you can add assumptions or other information you deem relevant to this dashboard page
A5: Purchase Price | C5: =5*10^6 -> 5000000
A6: Net Sale Price | C6: ='Yearly Cashflow'!H9/'Case Study'!B12 -> 9752109.1
A7: Net Cash Flow Before Debt (yearly) | C7: ='Yearly Cashflow'!H13 -> 681408.18
A8: Net Cash Flow After Debt (yearly) | C8: ='Yearly Cashflow'!H17 -> 443881.61
A10: Sources and Uses of Cash Flow | E10: Returns & Yields
A11: Sources | B11: Total | C11: % | E11: Equity Multiple | H11: =('Yearly Cashflow'!D17+'Yearly Cashflow'!E17+'Yearly Cashflow'!F17+'Yearly Cashflow'!G17+'Yearly Cashflow'!H17+'Yearly Cashflow'!H18)/Dashboard!B13 -> 9.3364328
A12: Debt | B12: =C12*$C$5 -> 3750000 | C12: 0.75 | E12: Levered IRR | H12: =IRR('Yearly Cashflow'!D20:H20) -> 0.26649991
A13: Equity | B13: =C13*$C$5 -> 1250000 | C13: =1-C12 -> 0.25 | E13: Levered Profit | H13: =SUM('Yearly Cashflow'!D17:H17) -> 1918431.9 | I13: in total
A14: Total | B14: =SUM(B12:B13) -> 5000000 | E14: Return on Equity | H14: ='Yearly Cashflow'!H17/Dashboard!B13 -> 0.35510528
A16: Uses | B16: Total | C16: %
A17: Acquisition | B17: =C17*C5 -> 35000 | C17: 0.007 | D17: (assumed)
A18: Loan Fee | B18: =C18*B12 -> 37500 | C18: 0.01
A19: Capital Expenditure | B19: =SUM('Yearly Cashflow'!D11:H11) -> 312500
A20: Total | B20: =SUM(B17:B19) -> 385000

Sheet Monthly Cashflow
A1: Analysis Date | B1: 44197 | D1: Triple Net Leases Anually(NNN)-CAM,Taxes,Insurance | E1: ='Case Study'!B48+'Case Study'!B49+'Case Study'!B50 -> 125000
A2: Rent Frequency in a year | B2: 12 | D2: Expenses Increment anually | E2: 0.02 | H2: =B1 -> 44197 | I2: =EOMONTH(H2,0) -> 44227 | J2: =EOMONTH(I2,1) -> 44255 | K2: =EOMONTH(J2,1) -> 44286 | L2: =EOMONTH(K2,1) -> 44316 | M2: =EOMONTH(L2,1) -> 44347 | N2: =EOMONTH(M2,1) -> 44377 | O2: =EOMONTH(N2,1) -> 44408 | P2: =EOMONTH(O2,1) -> 44439 | Q2: =EOMONTH(P2,1) -> 44469 | ... BP2: =EOMONTH(BO2,1) -> 46022
D3: Leasable Area | E3: 50000 | H3: 0 | I3: 1 | J3: 2 | K3: 3 | L3: 4 | M3: 5 | N3: 6 | O3: 7 | P3: 8 | Q3: 9 | R3: 10 | S3: 11 | T3: 12 | U3: 13 | V3: 14 | W3: 15 | X3: 16 | Y3: 17 | Z3: 18 | AA3: 19 | AB3: 20 | AC3: 21 | AD3: 22 | AE3: 23 | AF3: 24 | AG3: 25 | AH3: 26 | AI3: 27 | AJ3: 28 | AK3: 29 | AL3: 30 | AM3: 31 | AN3: 32 | AO3: 33 | AP3: 34 | AQ3: 35 | AR3: 36 | AS3: 37 | AT3: 38 | AU3: 39 | AV3: 40 | AW3: 41 | AX3: 42 | AY3: 43 | AZ3: 44 | BA3: 45 | BB3: 46 | BC3: 47 | BD3: 48 | BE3: 49 | BF3: 50 | BG3: 51 | BH3: 52 | BI3: 53 | BJ3: 54 | BK3: 55 | BL3: 56 | BM3: 57 | BN3: 58 | BO3: 59 | BP3: 60
A6: Income | F6: Total Rent
B7: Suite | C7: ='Case Study'!B30 -> Leased Area | D7: ='Case Study'!F30 -> Annual Rent PSF | E7: ='Case Study'!H30 -> Rent Increase | F7: as of 1st Jan 2021
B8: ='Case Study'!A32 -> 1001 | C8: ='Case Study'!B32 -> 10000 | D8: ='Case Study'!F32 -> 12.15 | E8: ='Case Study'!H32 -> 0.03 | F8: =D8*C8 -> 121500 | H8: =($F8/$B$2)*(1+$E8)^INT(H$3/$B$2) -> 10125 | I8: =($F8/$B$2)*(1+$E8)^INT(I$3/$B$2) -> 10125 | J8: =($F8/$B$2)*(1+$E8)^INT(J$3/$B$2) -> 10125 | K8: =($F8/$B$2)*(1+$E8)^INT(K$3/$B$2) -> 10125 | L8: =($F8/$B$2)*(1+$E8)^INT(L$3/$B$2) -> 10125 | M8: =($F8/$B$2)*(1+$E8)^INT(M$3/$B$2) -> 10125 | N8: =($F8/$B$2)*(1+$E8)^INT(N$3/$B$2) -> 10125 | O8: =($F8/$B$2)*(1+$E8)^INT(O$3/$B$2) -> 10125 | ... BP8: =($F8/$B$2)*(1+$E8)^INT(BP$3/$B$2) -> 11737.65
B9: ='Case Study'!A33 -> 1002 | C9: ='Case Study'!B33 -> 10000 | D9: ='Case Study'!F33 -> 11.5 | E9: ='Case Study'!H33 -> 0.03 | F9: =D9*C9 -> 115000 | H9: =($F9/$B$2)*(1+$E9)^INT(H$3/$B$2) -> 9583.3333 | I9: =($F9/$B$2)*(1+$E9)^INT(I$3/$B$2) -> 9583.3333 | J9: =($F9/$B$2)*(1+$E9)^INT(J$3/$B$2) -> 9583.3333 | K9: =($F9/$B$2)*(1+$E9)^INT(K$3/$B$2) -> 9583.3333 | L9: =($F9/$B$2)*(1+$E9)^INT(L$3/$B$2) -> 9583.3333 | M9: =($F9/$B$2)*(1+$E9)^INT(M$3/$B$2) -> 9583.3333 | N9: =($F9/$B$2)*(1+$E9)^INT(N$3/$B$2) -> 9583.3333 | O9: =($F9/$B$2)*(1+$E9)^INT(O$3/$B$2) -> 9583.3333 | ... BP9: =($F9/$B$2)*(1+$E9)^INT(BP$3/$B$2) -> 11109.71
B10: ='Case Study'!A34 -> 1003 | C10: ='Case Study'!B34 -> 15000 | D10: ='Case Study'!F34 -> 10.75 | E10: ='Case Study'!H34 -> 0.03 | F10: =D10*C10 -> 161250 | H10: =($F10/$B$2)*(1+$E10)^INT(H$3/$B$2) -> 13437.5 | I10: =($F10/$B$2)*(1+$E10)^INT(I$3/$B$2) -> 13437.5 | J10: =($F10/$B$2)*(1+$E10)^INT(J$3/$B$2) -> 13437.5 | K10: =($F10/$B$2)*(1+$E10)^INT(K$3/$B$2) -> 13437.5 | L10: =($F10/$B$2)*(1+$E10)^INT(L$3/$B$2) -> 13437.5 | M10: =($F10/$B$2)*(1+$E10)^INT(M$3/$B$2) -> 13437.5 | N10: =($F10/$B$2)*(1+$E10)^INT(N$3/$B$2) -> 13437.5 | O10: =($F10/$B$2)*(1+$E10)^INT(O$3/$B$2) -> 13437.5 | ... BP10: =($F10/$B$2)*(1+$E10)^INT(BP$3/$B$2) -> 15577.745
B11: ='Case Study'!A35 -> 1004 | C11: ='Case Study'!B35 -> 5000 | D11: ='Case Study'!F35 -> 12 | E11: ='Case Study'!H35 -> 0.05 | F11: =D11*C11 -> 60000 | H11: =($F11/$B$2)*(1+$E11)^INT(H$3/$B$2) -> 5000 | I11: =($F11/$B$2)*(1+$E11)^INT(I$3/$B$2) -> 5000 | J11: =($F11/$B$2)*(1+$E11)^INT(J$3/$B$2) -> 5000 | K11: =($F11/$B$2)*(1+$E11)^INT(K$3/$B$2) -> 5000 | L11: =($F11/$B$2)*(1+$E11)^INT(L$3/$B$2) -> 5000 | M11: =($F11/$B$2)*(1+$E11)^INT(M$3/$B$2) -> 5000 | N11: =($F11/$B$2)*(1+$E11)^INT(N$3/$B$2) -> 5000 | O11: =($F11/$B$2)*(1+$E11)^INT(O$3/$B$2) -> 5000 | ... BP11: =($F11/$B$2)*(1+$E11)^INT(BP$3/$B$2) -> 6381.4078
B12: ='Case Study'!A36 -> 1005 | C12: ='Case Study'!B36 -> 10000 | D12: ='Case Study'!F36 -> 12 | E12: ='Case Study'!H36 -> 0.05 | F12: =D12*C12 -> 120000 | H12: =($F12/$B$2)*(1+$E12)^INT(H$3/$B$2) -> 10000 | I12: =($F12/$B$2)*(1+$E12)^INT(I$3/$B$2) -> 10000 | J12: =($F12/$B$2)*(1+$E12)^INT(J$3/$B$2) -> 10000 | K12: =($F12/$B$2)*(1+$E12)^INT(K$3/$B$2) -> 10000 | L12: =($F12/$B$2)*(1+$E12)^INT(L$3/$B$2) -> 10000 | M12: =($F12/$B$2)*(1+$E12)^INT(M$3/$B$2) -> 10000 | N12: =($F12/$B$2)*(1+$E12)^INT(N$3/$B$2) -> 10000 | O12: =($F12/$B$2)*(1+$E12)^INT(O$3/$B$2) -> 10000 | ... BP12: =($F12/$B$2)*(1+$E12)^INT(BP$3/$B$2) -> 12762.816
B13: ='Case Study'!A37 -> 1006 | C13: ='Case Study'!B37 -> 6000
B15: Suite | C15: Proportion | D15: Annual share of triple Rent(NNN) as of 1st Jan 2021
B16: 1001 | C16: =C8/SUM($C$8:$C$12) -> 0.2 | D16: =C16*$E$1 -> 25000 | H16: =($D16/$B$2)*(1+$E$2)^INT(H$3/$B$2) -> 2083.3333 | I16: =($D16/$B$2)*(1+$E$2)^INT(I$3/$B$2) -> 2083.3333 | J16: =($D16/$B$2)*(1+$E$2)^INT(J$3/$B$2) -> 2083.3333 | K16: =($D16/$B$2)*(1+$E$2)^INT(K$3/$B$2) -> 2083.3333 | L16: =($D16/$B$2)*(1+$E$2)^INT(L$3/$B$2) -> 2083.3333 | M16: =($D16/$B$2)*(1+$E$2)^INT(M$3/$B$2) -> 2083.3333 | N16: =($D16/$B$2)*(1+$E$2)^INT(N$3/$B$2) -> 2083.3333 | O16: =($D16/$B$2)*(1+$E$2)^INT(O$3/$B$2) -> 2083.3333 | ... BP16: =($D16/$B$2)*(1+$E$2)^INT(BP$3/$B$2) -> 2300.1683
B17: 1002 | C17: =C9/SUM($C$8:$C$12) -> 0.2 | D17: =C17*$E$1 -> 25000 | H17: =($D17/$B$2)*(1+$E$2)^INT(H$3/$B$2) -> 2083.3333 | I17: =($D17/$B$2)*(1+$E$2)^INT(I$3/$B$2) -> 2083.3333 | J17: =($D17/$B$2)*(1+$E$2)^INT(J$3/$B$2) -> 2083.3333 | K17: =($D17/$B$2)*(1+$E$2)^INT(K$3/$B$2) -> 2083.3333 | L17: =($D17/$B$2)*(1+$E$2)^INT(L$3/$B$2) -> 2083.3333 | M17: =($D17/$B$2)*(1+$E$2)^INT(M$3/$B$2) -> 2083.3333 | N17: =($D17/$B$2)*(1+$E$2)^INT(N$3/$B$2) -> 2083.3333 | O17: =($D17/$B$2)*(1+$E$2)^INT(O$3/$B$2) -> 2083.3333 | ... BP17: =($D17/$B$2)*(1+$E$2)^INT(BP$3/$B$2) -> 2300.1683
B18: 1003 | C18: =C10/SUM($C$8:$C$12) -> 0.3 | D18: =C18*$E$1 -> 37500 | H18: =($D18/$B$2)*(1+$E$2)^INT(H$3/$B$2) -> 3125 | I18: =($D18/$B$2)*(1+$E$2)^INT(I$3/$B$2) -> 3125 | J18: =($D18/$B$2)*(1+$E$2)^INT(J$3/$B$2) -> 3125 | K18: =($D18/$B$2)*(1+$E$2)^INT(K$3/$B$2) -> 3125 | L18: =($D18/$B$2)*(1+$E$2)^INT(L$3/$B$2) -> 3125 | M18: =($D18/$B$2)*(1+$E$2)^INT(M$3/$B$2) -> 3125 | N18: =($D18/$B$2)*(1+$E$2)^INT(N$3/$B$2) -> 3125 | O18: =($D18/$B$2)*(1+$E$2)^INT(O$3/$B$2) -> 3125 | ... BP18: =($D18/$B$2)*(1+$E$2)^INT(BP$3/$B$2) -> 3450.2525
B19: 1004 | C19: =C11/SUM($C$8:$C$12) -> 0.1 | D19: =C19*$E$1 -> 12500 | H19: =($D19/$B$2)*(1+$E$2)^INT(H$3/$B$2) -> 1041.6667 | I19: =($D19/$B$2)*(1+$E$2)^INT(I$3/$B$2) -> 1041.6667 | J19: =($D19/$B$2)*(1+$E$2)^INT(J$3/$B$2) -> 1041.6667 | K19: =($D19/$B$2)*(1+$E$2)^INT(K$3/$B$2) -> 1041.6667 | L19: =($D19/$B$2)*(1+$E$2)^INT(L$3/$B$2) -> 1041.6667 | M19: =($D19/$B$2)*(1+$E$2)^INT(M$3/$B$2) -> 1041.6667 | N19: =($D19/$B$2)*(1+$E$2)^INT(N$3/$B$2) -> 1041.6667 | O19: =($D19/$B$2)*(1+$E$2)^INT(O$3/$B$2) -> 1041.6667 | ... BP19: =($D19/$B$2)*(1+$E$2)^INT(BP$3/$B$2) -> 1150.0842
B20: 1005 | C20: =C12/SUM($C$8:$C$12) -> 0.2 | D20: =C20*$E$1 -> 25000 | H20: =($D20/$B$2)*(1+$E$2)^INT(H$3/$B$2) -> 2083.3333 | I20: =($D20/$B$2)*(1+$E$2)^INT(I$3/$B$2) -> 2083.3333 | J20: =($D20/$B$2)*(1+$E$2)^INT(J$3/$B$2) -> 2083.3333 | K20: =($D20/$B$2)*(1+$E$2)^INT(K$3/$B$2) -> 2083.3333 | L20: =($D20/$B$2)*(1+$E$2)^INT(L$3/$B$2) -> 2083.3333 | M20: =($D20/$B$2)*(1+$E$2)^INT(M$3/$B$2) -> 2083.3333 | N20: =($D20/$B$2)*(1+$E$2)^INT(N$3/$B$2) -> 2083.3333 | O20: =($D20/$B$2)*(1+$E$2)^INT(O$3/$B$2) -> 2083.3333 | ... BP20: =($D20/$B$2)*(1+$E$2)^INT(BP$3/$B$2) -> 2300.1683
B21: 1006
A23: Operating Expenses | D23: Annual Expense as of 1st Jan 2021
B24: Utilities | D24: ='Case Study'!B51 -> 20000 | H24: =($D24/$B$2)*(1+$E$2)^INT(H$3/$B$2) -> 1666.6667 | I24: =($D24/$B$2)*(1+$E$2)^INT(I$3/$B$2) -> 1666.6667 | J24: =($D24/$B$2)*(1+$E$2)^INT(J$3/$B$2) -> 1666.6667 | K24: =($D24/$B$2)*(1+$E$2)^INT(K$3/$B$2) -> 1666.6667 | L24: =($D24/$B$2)*(1+$E$2)^INT(L$3/$B$2) -> 1666.6667 | M24: =($D24/$B$2)*(1+$E$2)^INT(M$3/$B$2) -> 1666.6667 | N24: =($D24/$B$2)*(1+$E$2)^INT(N$3/$B$2) -> 1666.6667 | O24: =($D24/$B$2)*(1+$E$2)^INT(O$3/$B$2) -> 1666.6667 | ... BP24: =($D24/$B$2)*(1+$E$2)^INT(BP$3/$B$2) -> 1840.1347
B25: Repairs | D25: ='Case Study'!B52 -> 45000 | H25: =($D25/$B$2)*(1+$E$2)^INT(H$3/$B$2) -> 3750 | I25: =($D25/$B$2)*(1+$E$2)^INT(I$3/$B$2) -> 3750 | J25: =($D25/$B$2)*(1+$E$2)^INT(J$3/$B$2) -> 3750 | K25: =($D25/$B$2)*(1+$E$2)^INT(K$3/$B$2) -> 3750 | L25: =($D25/$B$2)*(1+$E$2)^INT(L$3/$B$2) -> 3750 | M25: =($D25/$B$2)*(1+$E$2)^INT(M$3/$B$2) -> 3750 | N25: =($D25/$B$2)*(1+$E$2)^INT(N$3/$B$2) -> 3750 | O25: =($D25/$B$2)*(1+$E$2)^INT(O$3/$B$2) -> 3750 | ... BP25: =($D25/$B$2)*(1+$E$2)^INT(BP$3/$B$2) -> 4140.303
A27: NOI | H27: =SUM(H8:H12)+SUM(H16:H20)-SUM(H24:H25) -> 53145.833 | I27: =SUM(I8:I12)+SUM(I16:I20)-SUM(I24:I25) -> 53145.833 | J27: =SUM(J8:J12)+SUM(J16:J20)-SUM(J24:J25) -> 53145.833 | K27: =SUM(K8:K12)+SUM(K16:K20)-SUM(K24:K25) -> 53145.833 | L27: =SUM(L8:L12)+SUM(L16:L20)-SUM(L24:L25) -> 53145.833 | M27: =SUM(M8:M12)+SUM(M16:M20)-SUM(M24:M25) -> 53145.833 | N27: =SUM(N8:N12)+SUM(N16:N20)-SUM(N24:N25) -> 53145.833 | O27: =SUM(O8:O12)+SUM(O16:O20)-SUM(O24:O25) -> 53145.833 | ... BP27: =SUM(BP8:BP12)+SUM(BP16:BP20)-SUM(BP24:BP25) -> 63089.733
B29: 2021 | C29: 2022 | D29: 2023 | E29: 2024 | F29: 2025
A30: Capital Expense | B30: =VLOOKUP(B29,'Case Study'!$A$59:$B$63,COLUMNS('Case Study'!A64:B64))*$E$3 -> 100000 | C30: =VLOOKUP(C29,'Case Study'!$A$59:$B$63,COLUMNS('Case Study'!B64:C64))*$E$3 -> 62500 | D30: =VLOOKUP(D29,'Case Study'!$A$59:$B$63,COLUMNS('Case Study'!C64:D64))*$E$3 -> 50000 | E30: =VLOOKUP(E29,'Case Study'!$A$59:$B$63,COLUMNS('Case Study'!D64:E64))*$E$3 -> 50000 | F30: =VLOOKUP(F29,'Case Study'!$A$59:$B$63,COLUMNS('Case Study'!E64:F64))*$E$3 -> 50000 | H30: =$B$30/$B$2 -> 8333.3333 | I30: =$B$30/$B$2 -> 8333.3333 | J30: =$B$30/$B$2 -> 8333.3333 | K30: =$B$30/$B$2 -> 8333.3333 | L30: =$B$30/$B$2 -> 8333.3333 | M30: =$B$30/$B$2 -> 8333.3333 | N30: =$B$30/$B$2 -> 8333.3333 | O30: =$B$30/$B$2 -> 8333.3333 | ... S30: =$B$30/$B$2 -> 8333.3333 | T30: =$C$30/$B$2 -> 5208.3333 | U30: =$C$30/$B$2 -> 5208.3333 | V30: =$C$30/$B$2 -> 5208.3333 | W30: =$C$30/$B$2 -> 5208.3333 | X30: =$C$30/$B$2 -> 5208.3333 | Y30: =$C$30/$B$2 -> 5208.3333 | Z30: =$C$30/$B$2 -> 5208.3333 | AA30: =$C$30/$B$2 -> 5208.3333 | ... AE30: =$C$30/$B$2 -> 5208.3333 | AF30: =$D$30/$B$2 -> 4166.6667 | AG30: =$D$30/$B$2 -> 4166.6667 | AH30: =$D$30/$B$2 -> 4166.6667 | AI30: =$D$30/$B$2 -> 4166.6667 | AJ30: =$D$30/$B$2 -> 4166.6667 | AK30: =$D$30/$B$2 -> 4166.6667 | AL30: =$D$30/$B$2 -> 4166.6667 | AM30: =$D$30/$B$2 -> 4166.6667 | ... AQ30: =$D$30/$B$2 -> 4166.6667 | AR30: =$E$30/$B$2 -> 4166.6667 | AS30: =$E$30/$B$2 -> 4166.6667 | AT30: =$E$30/$B$2 -> 4166.6667 | AU30: =$E$30/$B$2 -> 4166.6667 | AV30: =$E$30/$B$2 -> 4166.6667 | AW30: =$E$30/$B$2 -> 4166.6667 | AX30: =$E$30/$B$2 -> 4166.6667 | AY30: =$E$30/$B$2 -> 4166.6667 | ... BC30: =$E$30/$B$2 -> 4166.6667 | BD30: =$F$30/$B$2 -> 4166.6667 | BE30: =$F$30/$B$2 -> 4166.6667 | BF30: =$F$30/$B$2 -> 4166.6667 | BG30: =$F$30/$B$2 -> 4166.6667 | BH30: =$F$30/$B$2 -> 4166.6667 | BI30: =$F$30/$B$2 -> 4166.6667 | BJ30: =$F$30/$B$2 -> 4166.6667 | BK30: =$F$30/$B$2 -> 4166.6667 | ... BP30: =$F$30/$B$2 -> 4166.6667
A32: Cash flow Before Debt | H32: =H27-H30 -> 44812.5 | I32: =I27-I30 -> 44812.5 | J32: =J27-J30 -> 44812.5 | K32: =K27-K30 -> 44812.5 | L32: =L27-L30 -> 44812.5 | M32: =M27-M30 -> 44812.5 | N32: =N27-N30 -> 44812.5 | O32: =O27-O30 -> 44812.5 | ... BP32: =BP27-BP30 -> 58923.066
A34: Interest Expense | I34: ='Amortization of Loan'!I7 -> 19793.882 | J34: ='Amortization of Loan'!$I$7 -> 19793.882 | K34: ='Amortization of Loan'!$I$7 -> 19793.882 | L34: ='Amortization of Loan'!$I$7 -> 19793.882 | M34: ='Amortization of Loan'!$I$7 -> 19793.882 | N34: ='Amortization of Loan'!$I$7 -> 19793.882 | O34: ='Amortization of Loan'!$I$7 -> 19793.882 | P34: ='Amortization of Loan'!$I$7 -> 19793.882 | Q34: ='Amortization of Loan'!$I$7 -> 19793.882 | ... BP34: ='Amortization of Loan'!$I$7 -> 19793.882
A36: Cash Flow After Debt | H36: =H32-H34 -> 44812.5 | I36: =I32-I34 -> 25018.618 | J36: =J32-J34 -> 25018.618 | K36: =K32-K34 -> 25018.618 | L36: =L32-L34 -> 25018.618 | M36: =M32-M34 -> 25018.618 | N36: =N32-N34 -> 25018.618 | O36: =O32-O34 -> 25018.618 | ... BP36: =BP32-BP34 -> 39129.185

Sheet Yearly Cashflow
A2: * Summarize the monthly Cash flow Annually here
D3: 1 | E3: 2 | F3: 3 | G3: 4 | H3: 5
B5: Income | D5: =SUM('Monthly Cashflow'!H7:H20)*12 -> 702750 | E5: =SUM('Monthly Cashflow'!T8:AE20) -> 726182.5 | F5: =SUM('Monthly Cashflow'!AF8:AQ21) -> 750472.98 | G5: =SUM('Monthly Cashflow'!AR8:AR20)*12 -> 775655.66 | H5: =SUM('Monthly Cashflow'!BD8:BD21)*12 -> 801766.27
B7: Operating Expenses | D7: =SUM('Monthly Cashflow'!H24:H25)*12 -> 65000 | E7: =SUM('Monthly Cashflow'!T24:T25)*12 -> 66300 | F7: =SUM('Monthly Cashflow'!AF24:AF25)*12 -> 67626 | G7: =SUM('Monthly Cashflow'!AR24:AR25)*12 -> 68978.52 | H7: =SUM('Monthly Cashflow'!BD24:BD25)*12 -> 70358.09
B9: NOI | D9: =D5-D7 -> 637750 | E9: =E5-E7 -> 659882.5 | F9: =F5-F7 -> 682846.98 | G9: =G5-G7 -> 706677.14 | H9: =H5-H7 -> 731408.18
B11: Capital Expense | D11: ='Monthly Cashflow'!B30 -> 100000 | E11: ='Monthly Cashflow'!C30 -> 62500 | F11: ='Monthly Cashflow'!D30 -> 50000 | G11: ='Monthly Cashflow'!E30 -> 50000 | H11: ='Monthly Cashflow'!F30 -> 50000
B13: Cash flow Before Debt | D13: =D9-D11 -> 537750 | E13: =E9-E11 -> 597382.5 | F13: =F9-F11 -> 632846.98 | G13: =G9-G11 -> 656677.14 | H13: =H9-H11 -> 681408.18
B15: Interest Expense | D15: ='Amortization of Loan'!$I$7*12 -> 237526.58 | E15: ='Amortization of Loan'!$I$7*12 -> 237526.58 | F15: ='Amortization of Loan'!$I$7*12 -> 237526.58 | G15: ='Amortization of Loan'!$I$7*12 -> 237526.58 | H15: ='Amortization of Loan'!$I$7*12 -> 237526.58
B17: Cash Flow After Debt | D17: =D13-D15 -> 300223.42 | E17: =E13-E15 -> 359855.92 | F17: =F13-F15 -> 395320.4 | G17: =G13-G15 -> 419150.57 | H17: =H13-H15 -> 443881.61
D18: =-Dashboard!C5 -> -5000000 | H18: =Dashboard!C6 -> 9752109.1
B20: CF for NPV,IRR Calculation | D20: =D17+D18 -> -4699776.6 | E20: =E17 -> 359855.92 | F20: =F17 -> 395320.4 | G20: =G17 -> 419150.57 | H20: =H18+H17 -> 10195991

Sheet Amortization of Loan
B3: Loan Amortization Schedule
B6: Mortgage Amount | E6: =Dashboard!B12 -> 3750000 | G6: Monthly Interest Rate | I6: =E8/12 -> 0.0033333333
B7: Borrowing Term | E7: 25 | G7: Monthly Payment | I7: =PMT($I$6,$I$8,-E6,,) -> 19793.882
B8: Annual Interest Rate | E8: 0.04 | G8: Number of Periods | I8: =E7*12 -> 300
B10: Month | C10: Beginning Balance | D10: Payment | E10: Interest | F10: Principal | G10: Ending Balance | H10: % Interest | I10: % Principal
B11: 1 | C11: =E6 -> 3750000 | D11: =$I$7 -> 19793.882 | E11: =C11*$I$6 -> 12500 | F11: =D11-E11 -> 7293.8815 | G11: =C11-F11 -> 3742706.1 | H11: =E11/D11 -> 0.63150828 | I11: =F11/D11 -> 0.36849172
B12: =B11+1 -> 2 | C12: =G11 -> 3742706.1 | D12: =$I$7 -> 19793.882 | E12: =C12*$I$6 -> 12475.687 | F12: =D12-E12 -> 7318.1944 | G12: =C12-F12 -> 3735387.9 | H12: =E12/D12 -> 0.63027997 | I12: =F12/D12 -> 0.36972003
B13: =B12+1 -> 3 | C13: =G12 -> 3735387.9 | D13: =$I$7 -> 19793.882 | E13: =C13*$I$6 -> 12451.293 | F13: =D13-E13 -> 7342.5884 | G13: =C13-F13 -> 3728045.3 | H13: =E13/D13 -> 0.62904757 | I13: =F13/D13 -> 0.37095243
B14: =B13+1 -> 4 | C14: =G13 -> 3728045.3 | D14: =$I$7 -> 19793.882 | E14: =C14*$I$6 -> 12426.818 | F14: =D14-E14 -> 7367.0637 | G14: =C14-F14 -> 3720678.3 | H14: =E14/D14 -> 0.62781106 | I14: =F14/D14 -> 0.37218894
B15: =B14+1 -> 5 | C15: =G14 -> 3720678.3 | D15: =$I$7 -> 19793.882 | E15: =C15*$I$6 -> 12402.261 | F15: =D15-E15 -> 7391.6206 | G15: =C15-F15 -> 3713286.7 | H15: =E15/D15 -> 0.62657043 | I15: =F15/D15 -> 0.37342957
B16: =B15+1 -> 6 | C16: =G15 -> 3713286.7 | D16: =$I$7 -> 19793.882 | E16: =C16*$I$6 -> 12377.622 | F16: =D16-E16 -> 7416.2593 | G16: =C16-F16 -> 3705870.4 | H16: =E16/D16 -> 0.62532567 | I16: =F16/D16 -> 0.37467433
B17: =B16+1 -> 7 | C17: =G16 -> 3705870.4 | D17: =$I$7 -> 19793.882 | E17: =C17*$I$6 -> 12352.901 | F17: =D17-E17 -> 7440.9802 | G17: =C17-F17 -> 3698429.4 | H17: =E17/D17 -> 0.62407675 | I17: =F17/D17 -> 0.37592325
B18: =B17+1 -> 8 | C18: =G17 -> 3698429.4 | D18: =$I$7 -> 19793.882 | E18: =C18*$I$6 -> 12328.098 | F18: =D18-E18 -> 7465.7835 | G18: =C18-F18 -> 3690963.6 | H18: =E18/D18 -> 0.62282368 | I18: =F18/D18 -> 0.37717632
B19: =B18+1 -> 9 | C19: =G18 -> 3690963.6 | D19: =$I$7 -> 19793.882 | E19: =C19*$I$6 -> 12303.212 | F19: =D19-E19 -> 7490.6694 | G19: =C19-F19 -> 3683473 | H19: =E19/D19 -> 0.62156642 | I19: =F19/D19 -> 0.37843358
B20: =B19+1 -> 10 | C20: =G19 -> 3683473 | D20: =$I$7 -> 19793.882 | E20: =C20*$I$6 -> 12278.243 | F20: =D20-E20 -> 7515.6383 | G20: =C20-F20 -> 3675957.3 | H20: =E20/D20 -> 0.62030498 | I20: =F20/D20 -> 0.37969502
B21: =B20+1 -> 11 | C21: =G20 -> 3675957.3 | D21: =$I$7 -> 19793.882 | E21: =C21*$I$6 -> 12253.191 | F21: =D21-E21 -> 7540.6904 | G21: =C21-F21 -> 3668416.6 | H21: =E21/D21 -> 0.61903933 | I21: =F21/D21 -> 0.38096067
B22: =B21+1 -> 12 | C22: =G21 -> 3668416.6 | D22: =$I$7 -> 19793.882 | E22: =C22*$I$6 -> 12228.055 | F22: =D22-E22 -> 7565.8261 | G22: =C22-F22 -> 3660850.8 | H22: =E22/D22 -> 0.61776946 | I22: =F22/D22 -> 0.38223054
B23: =B22+1 -> 13 | C23: =G22 -> 3660850.8 | D23: =$I$7 -> 19793.882 | E23: =C23*$I$6 -> 12202.836 | F23: =D23-E23 -> 7591.0455 | G23: =C23-F23 -> 3653259.8 | H23: =E23/D23 -> 0.61649536 | I23: =F23/D23 -> 0.38350464
... B310: =B309+1 -> 300 | C310: =G309 -> 19728.121 | D310: =$I$7 -> 19793.882 | E310: =C310*$I$6 -> 65.760404 | F310: =D310-E310 -> 19728.121 | G310: =C310-F310 -> -6.51562e-09 | H310: =E310/D310 -> 0.0033222591 | I310: =F310/D310 -> 0.99667774
